#VRML_SIM R2019a utf8
WorldInfo {
}
Viewpoint {
  orientation -0.008100291140499703 -0.9066724332304871 -0.4217576129761588 3.106769009667518
  position -0.23305145601076516 0.704529884184881 -0.6421589798707492
}
TexturedBackground {
}
TexturedBackgroundLight {
}
Floor {
}
Robot {
  translation -0.05511759991373979 0.07385649017747987 0.005765180628466553
  rotation 0.0017961575308767111 0.9920698408772524 0.12567499608079372 0.028874397401134025
  children [
    DEF DEF_SH_BODY Group {
      children [
        Shape {
          appearance PBRAppearance {
            baseColor 0.9372549019607843 0.1607843137254902 0.1607843137254902
            roughness 1
            metalness 0
          }
          geometry Box {
            size 0.25 0.08 0.1
          }
        }
        Transform {
          translation -0.1075 -0.057 0
          children [
            Shape {
              appearance PBRAppearance {
                baseColor 0.9294117647058824 0.8313725490196079 0
                roughness 1
                metalness 0
              }
              geometry Sphere {
                radius 0.0175
              }
            }
          ]
        }
      ]
    }
    HingeJoint {
      jointParameters HingeJointParameters {
        position 0.4243369830596586
        axis 0 0 1
        anchor 0.05 0 0.065
      }
      endPoint Solid {
        translation 0.05 0 0.065
        rotation 0.9565970771911498 0.20606105630458194 0.20606036247660342 1.6151581394353332
        children [
          Shape {
            appearance DEF ColorRueda PBRAppearance {
              baseColor 0 0 0
              roughness 1
              metalness 0
            }
            geometry DEF Rueda1 Cylinder {
              height 0.03
              radius 0.075
            }
          }
        ]
        boundingObject USE Rueda1
        physics Physics {
        }
        linearVelocity 5.671275361541858e-07 -2.768285931539874e-07 -2.2668197701915154e-06
        angularVelocity 3.2239428814870723e-07 -1.5053637086977037e-06 -8.437055740428107e-06
      }
    }
    HingeJoint {
      jointParameters HingeJointParameters {
        position 0.7564747639659494
        axis 0 0 1
        anchor 0.05 0 -0.065
      }
      endPoint Solid {
        translation 0.05 0 -0.065
        rotation 0.8717745381602398 0.3464173514356982 0.34641618501417737 1.707595455914904
        children [
          Shape {
            appearance USE ColorRueda
            geometry USE Rueda1
          }
        ]
        name "solid(1)"
        boundingObject USE Rueda1
        physics Physics {
        }
        linearVelocity 7.313426551393564e-07 -2.603476543292396e-07 2.276347355525067e-06
        angularVelocity -1.3727252319820005e-07 -1.54510081301125e-06 -8.877733747052324e-06
      }
    }
  ]
  boundingObject USE DEF_SH_BODY
  physics Physics {
  }
  linearVelocity 6.426277296197105e-07 1.682813774075805e-07 2.7375877667940626e-08
  angularVelocity -1.1642112390218859e-07 -2.574367461034458e-07 -8.638214439941267e-06
}
