#VRML_SIM R2019a utf8
WorldInfo {
}
Viewpoint {
  orientation 0.028879745602463952 -0.9533295050243918 -0.3005475255993381 3.324294450264417
  position -0.09880271666331282 0.5673862128275967 -0.818401368161712
}
TexturedBackground {
}
TexturedBackgroundLight {
}
Floor {
}
Robot {
  translation -0.05511759991373979 0.07385649017747987 0.005765180628466553
  rotation 0.0017961575308767111 0.9920698408772524 0.12567499608079372 0.028874397401134025
  children [
    DEF DEF_SH_BODY Group {
      children [
        Shape {
          appearance PBRAppearance {
            baseColor 0.9372549019607843 0.1607843137254902 0.1607843137254902
            roughness 1
            metalness 0
          }
          geometry Box {
            size 0.25 0.08 0.1
          }
        }
        Transform {
          translation -0.1075 -0.057 0
          children [
            Shape {
              appearance PBRAppearance {
                baseColor 0.9294117647058824 0.8313725490196079 0
                roughness 1
                metalness 0
              }
              geometry Sphere {
                radius 0.0175
              }
            }
          ]
        }
      ]
    }
    HingeJoint {
      jointParameters HingeJointParameters {
        position 0.4243369830596586
        axis 0 0 1
        anchor 0.05 0 0.065
      }
      device [
        RotationalMotor {
          name "motor_right"
          maxVelocity 524
          maxTorque 0.03
        }
      ]
      endPoint Solid {
        translation 0.05 0 0.065
        rotation 0.9565970771911498 0.20606105630458188 0.20606036247660345 1.6151581394353332
        children [
          Shape {
            appearance DEF ColorRueda PBRAppearance {
              baseColor 0 0 0
              roughness 1
              metalness 0
            }
            geometry DEF Rueda1 Cylinder {
              height 0.03
              radius 0.075
            }
          }
        ]
        boundingObject USE Rueda1
        physics Physics {
        }
      }
    }
    HingeJoint {
      jointParameters HingeJointParameters {
        position 0.7564747639659494
        axis 0 0 1
        anchor 0.05 0 -0.065
      }
      device [
        RotationalMotor {
          name "motor_left"
          maxVelocity 524
          maxTorque 0.03
        }
      ]
      endPoint Solid {
        translation 0.05 0 -0.065
        rotation 0.8717745381602398 0.34641735143569813 0.3464161850141773 1.707595455914904
        children [
          Shape {
            appearance USE ColorRueda
            geometry USE Rueda1
          }
        ]
        name "solid(1)"
        boundingObject USE Rueda1
        physics Physics {
        }
      }
    }
  ]
  boundingObject USE DEF_SH_BODY
  physics Physics {
  }
}
