#VRML_SIM R2019a utf8
WorldInfo {
}
Viewpoint {
  orientation -0.002877663011657437 -0.9887074050251662 -0.1498311926936225 3.1036189209618295
  position -0.17132433101307837 0.3680854168952746 -0.9163222845972729
}
TexturedBackground {
}
TexturedBackgroundLight {
}
Floor {
}
Robot {
  translation 0 0.2 0
  children [
    DEF DEF_SH_BODY Group {
      children [
        Shape {
          appearance PBRAppearance {
            baseColor 0.9372549019607843 0.1607843137254902 0.1607843137254902
            roughness 1
            metalness 0
          }
          geometry Box {
            size 0.25 0.08 0.1
          }
        }
        Transform {
          translation -0.1075 -0.057 0
          children [
            Shape {
              appearance PBRAppearance {
                baseColor 0.9294117647058824 0.8313725490196079 0
                roughness 1
                metalness 0
              }
              geometry Sphere {
                radius 0.0175
              }
            }
          ]
        }
      ]
    }
    HingeJoint {
      jointParameters HingeJointParameters {
        anchor 0.05 0 0.065
      }
      endPoint Solid {
        translation 0.05 0 0.065
        rotation 1 0 0 1.5707996938995747
        children [
          Shape {
            appearance DEF ColorRueda PBRAppearance {
              baseColor 0 0 0
              roughness 1
              metalness 0
            }
            geometry DEF Rueda1 Cylinder {
              height 0.03
              radius 0.075
            }
          }
        ]
        boundingObject USE Rueda1
        physics Physics {
        }
      }
    }
    HingeJoint {
      jointParameters HingeJointParameters {
        anchor 0.05 0 -0.065
      }
      endPoint Solid {
        translation 0.05 0 -0.065
        rotation 1 0 0 1.5707996938995747
        children [
          Shape {
            appearance USE ColorRueda
            geometry USE Rueda1
          }
        ]
        name "solid(1)"
        boundingObject USE Rueda1
        physics Physics {
        }
      }
    }
  ]
  boundingObject USE DEF_SH_BODY
  physics Physics {
  }
}
